<?xml version="1.0"?>
<robot xmlns:xacro="http://www.ros.org/wiki/xacro">

  <xacro:macro name="wheel">
    <link name="link_left_forward">
      <visual>
        <origin xyz="0 0 0" rpy="0 0 0" />
        <geometry>
          <mesh filename="package://mecanum_description/meshes/link_left_forward.STL" />
        </geometry>
        <material name="">
          <color rgba="0.79216 0.81961 0.93333 1" />
        </material>
      </visual>
      <collision>
        <origin xyz="0 0 0" rpy="0 0 0" />
        <geometry>
          <cylinder length="0.045" radius="0.097"/>
        </geometry>
      </collision>
      <inertial>
        <origin xyz="-0.00096963 -3.3007E-05 -0.025265" rpy="0 0 0" />
        <mass value="0.3"/>
        <!-- [kg] -->
        <inertia ixx="0.00031" ixy="0.0" ixz="0.0" iyy="0.00031" iyz="0.0" izz="0.00054"/>
      </inertial>


    </link>
    <joint name="joint_left_forward" type="continuous">
      <origin xyz="0.13483 0.22927 -0.018987" rpy="-1.5708 0 0" />
      <parent link="base_link" />
      <child link="link_left_forward" />
      <axis xyz="0 0 1" />
    </joint>
    <link name="link_right_forward">
      <visual>
        <origin xyz="0 0 0" rpy="0 0 0" />
        <geometry>
          <mesh filename="package://mecanum_description/meshes/link_right_forward.STL" />
        </geometry>
        <material name="">
          <color rgba="0.79216 0.81961 0.93333 1" />
        </material>
      </visual>
      <collision>
        <origin xyz="0 0 0" rpy="0 0 0" />
        <geometry>
          <cylinder length="0.045" radius="0.097"/>
        </geometry>
      </collision>
      <inertial>
        <origin xyz="0.00098278 -4.0254E-05 0.025261" rpy="0 0 0" />
        <mass value="0.3"/>
        <!-- [kg] -->
        <inertia ixx="0.00031" ixy="0.0" ixz="0.0" iyy="0.00031" iyz="0.0" izz="0.00054"/>
      </inertial>


    </link>
    <joint name="joint_right_forward" type="continuous">
      <origin xyz="0.13482 -0.22927 -0.018987" rpy="-1.5708 0 0" />
      <parent link="base_link" />
      <child link="link_right_forward" />
      <axis xyz="0 0 1" />
    </joint>



    <link name="link_left_back">
      <visual>
        <origin xyz="0 0 0" rpy="0 0 0" />
        <geometry>
          <mesh filename="package://mecanum_description/meshes/link_left_back.STL" />
        </geometry>
        <material name="">
          <color rgba="0.79216 0.81961 0.93333 1" />
        </material>
      </visual>
      <collision>
        <origin xyz="0 0 0" rpy="0 0 0" />
        <geometry>
          <cylinder length="0.045" radius="0.097"/>
        </geometry>
      </collision>
      <inertial>
        <origin xyz="-0.00098278 -4.0253E-05 -0.025261" rpy="0 0 0" />
        <mass value="0.3"/>
        <!-- [kg] -->
        <inertia ixx="0.00031" ixy="0.0" ixz="0.0" iyy="0.00031" iyz="0.0" izz="0.00054"/>
      </inertial>


    </link>
    <joint name="joint_left_back" type="continuous">
      <origin xyz="-0.13482 0.22927 -0.018987" rpy="-1.5708 0 0" />
      <parent link="base_link" />
      <child link="link_left_back" />
      <axis xyz="0 0 1" />
    </joint>



    <link name="link_right_back">
      <visual>
        <origin xyz="0 0 0" rpy="0 0 0" />
        <geometry>
          <mesh filename="package://mecanum_description/meshes/link_right_back.STL" />
        </geometry>
        <material name="">
          <color rgba="0.79216 0.81961 0.93333 1" />
        </material>
      </visual>
      <collision>
        <origin xyz="0 0 0" rpy="0 0 0" />
        <geometry>
          <cylinder length="0.045" radius="0.097"/>
        </geometry>
      </collision>
      <inertial>
        <origin xyz="0.0009961 -2.2144E-05 0.025277" rpy="0 0 0" />
        <mass value="0.3"/>
        <!-- [kg] -->
        <inertia ixx="0.00031" ixy="0.0" ixz="0.0" iyy="0.00031" iyz="0.0" izz="0.00054"/>
      </inertial>


    </link>
    <joint name="joint_right_back" type="continuous">
      <origin xyz="-0.13483 -0.22927 -0.018987" rpy="-1.5708 0 0" />
      <parent link="base_link" />
      <child link="link_right_back" />
      <axis xyz="0 0 1" />
    </joint>
  </xacro:macro>

</robot>
