<?xml version="1.0" encoding="utf-8"?>
<!-- This URDF was automatically created by SolidWorks to URDF Exporter! Originally created by Stephen Brawner (brawner@gmail.com) 
     Commit Version: 1.5.1-0-g916b5db  Build Version: 1.5.7152.31018
     For more information, please see http://wiki.ros.org/sw_urdf_exporter -->
<robot name="mecanum_car">
  <link name="base_footprint" />
  </link>

  <joint name="joint_base" type="fixed">
    <origin xyz="0 0 0.065" rpy="0 0 0" />
    <parent link="base_footprint" />
    <child link="base_link" />
  </joint>

  <link name="base_link">
    <inertial>
      <origin xyz="-6.0432E-15 -5.0793E-15 0.072853" rpy="0 0 0" />
      <mass value="2.1346" />
      <inertia ixx="0.01177" ixy="2.0442E-13" ixz="-1.1397E-17" iyy="0.026675" iyz="2.6636E-17" izz="0.038171" />
    </inertial>
    <visual>
      <origin xyz="0 0 0" rpy="0 0 0" />
      <geometry>
        <mesh filename="package://mecanum_description/meshes/base_link.STL" />
      </geometry>
      <material name="">
        <color rgba="0.79216 0.81961 0.93333 1" />
      </material>
    </visual>
    <collision>
      <origin xyz="0 0 0" rpy="0 0 0" />
      <geometry>
        <mesh filename="package://mecanum_description/meshes/base_link.STL" />
      </geometry>
    </collision>
  </link>
  <link name="link_left_forward">
    <inertial>
      <origin xyz="-0.00096963 -3.3007E-05 -0.025265" rpy="0 0 0" />
      <mass value="0.2092" />
      <inertia ixx="6.2889E-05" ixy="-4.629E-08" ixz="-4.7415E-08" iyy="6.3092E-05" iyz="2.1786E-07" izz="9.6713E-05" />
    </inertial>
    <visual>
      <origin xyz="0 0 0" rpy="0 0 0" />
      <geometry>
        <mesh filename="package://mecanum_description/meshes/link_left_forward.STL" />
      </geometry>
      <material name="">
        <color rgba="0.79216 0.81961 0.93333 1" />
      </material>
    </visual>
    <collision>
      <origin xyz="0 0 0" rpy="0 0 0" />
      <geometry>
        <mesh filename="package://mecanum_description/meshes/link_left_forward.STL" />
      </geometry>
    </collision>
  </link>

  <joint name="joint_left_forward" type="continuous">
    <origin xyz="0.13483 0.22927 -0.018987" rpy="-1.5708 0 0" />
    <parent link="base_link" />
    <child link="link_left_forward" />
    <axis xyz="0 0 1" />
    <dynamics damping="0.1" friction="0.1" />
  </joint>
  <link name="link_right_forward">
    <inertial>
      <origin xyz="0.00098278 -4.0254E-05 0.025261" rpy="0 0 0" />
      <mass value="0.20913" />
      <inertia ixx="6.2889E-05" ixy="4.6229E-08" ixz="-4.7323E-08" iyy="6.3091E-05" iyz="-2.1778E-07" izz="9.6712E-05" />
    </inertial>
    <visual>
      <origin xyz="0 0 0" rpy="0 0 0" />
      <geometry>
        <mesh filename="package://mecanum_description/meshes/link_right_forward.STL" />
      </geometry>
      <material name="">
        <color rgba="0.79216 0.81961 0.93333 1" />
      </material>
    </visual>
    <collision>
      <origin xyz="0 0 0" rpy="0 0 0" />
      <geometry>
        <mesh filename="package://mecanum_description/meshes/link_right_forward.STL" />
      </geometry>
    </collision>
  </link>
  <joint name="joint_right_forward" type="continuous">
    <origin xyz="0.13482 -0.22927 -0.018987" rpy="-1.5708 0 0" />
    <parent link="base_link" />
    <child link="link_right_forward" />
    <axis xyz="0 0 1" />
    <dynamics damping="0.1" friction="0.1" />
  </joint>
  <link name="link_left_back">
    <inertial>
      <origin xyz="-0.00098278 -4.0253E-05 -0.025261" rpy="0 0 0" />
      <mass value="0.20913" />
      <inertia ixx="6.2889E-05" ixy="-4.6232E-08" ixz="-4.7321E-08" iyy="6.3091E-05" iyz="2.1778E-07" izz="9.6712E-05" />
    </inertial>
    <visual>
      <origin xyz="0 0 0" rpy="0 0 0" />
      <geometry>
        <mesh filename="package://mecanum_description/meshes/link_left_back.STL" />
      </geometry>
      <material name="">
        <color rgba="0.79216 0.81961 0.93333 1" />
      </material>
    </visual>
    <collision>
      <origin xyz="0 0 0" rpy="0 0 0" />
      <geometry>
        <mesh filename="package://mecanum_description/meshes/link_left_back.STL" />
      </geometry>
    </collision>
  </link>
  <joint name="joint_left_back" type="continuous">
    <origin xyz="-0.13482 0.22927 -0.018987" rpy="-1.5708 0 0" />
    <parent link="base_link" />
    <child link="link_left_back" />
    <axis xyz="0 0 1" />
    <dynamics damping="0.1" friction="0.1" />
  </joint>
  <link name="link_right_back">
    <inertial>
      <origin xyz="0.0009961 -2.2144E-05 0.025277" rpy="0 0 0" />
      <mass value="0.20906" />
      <inertia ixx="6.2888E-05" ixy="4.6395E-08" ixz="-4.7572E-08" iyy="6.3091E-05" iyz="-2.1769E-07" izz="9.6712E-05" />
    </inertial>
    <visual>
      <origin xyz="0 0 0" rpy="0 0 0" />
      <geometry>
        <mesh filename="package://mecanum_description/meshes/link_right_back.STL" />
      </geometry>
      <material name="">
        <color rgba="0.79216 0.81961 0.93333 1" />
      </material>
    </visual>
    <collision>
      <origin xyz="0 0 0" rpy="0 0 0" />
      <geometry>
        <mesh filename="package://mecanum_description/meshes/link_right_back.STL" />
      </geometry>
    </collision>
  </link>
  <joint name="joint_right_back" type="continuous">
    <origin xyz="-0.13483 -0.22927 -0.018987" rpy="-1.5708 0 0" />
    <parent link="base_link" />
    <child link="link_right_back" />
    <axis xyz="0 0 1" />
    <dynamics damping="0.1" friction="0.1" />
  </joint>
  <link name="link_rplidarA1">
    <inertial>
      <origin xyz="0.0057842 0.0004951 0.0039383" rpy="0 0 0" />
      <mass value="0.14299" />
      <inertia ixx="4.6277E-05" ixy="-8.5349E-07" ixz="3.6217E-06" iyy="7.3474E-05" iyz="-2.0431E-07" izz="0.00010796" />
    </inertial>
    <visual>
      <origin xyz="0 0 0" rpy="0 0 0" />
      <geometry>
        <mesh filename="package://mecanum_description/meshes/link_rplidarA1.STL" />
      </geometry>
      <material name="">
        <color rgba="0.79216 0.81961 0.93333 1" />
      </material>
    </visual>
    <collision>
      <origin xyz="0 0 0" rpy="0 0 0" />
      <geometry>
        <mesh filename="package://mecanum_description/meshes/link_rplidarA1.STL" />
      </geometry>
    </collision>
  </link>
  <joint name="joint_rplidarA1" type="fixed">
    <origin xyz="0.060113 0 0.2011" rpy="0 0 0" />
    <parent link="base_link" />
    <child link="link_rplidarA1" />
    <axis xyz="0 0 1" />
    <dynamics damping="0.1" friction="0.1" />
  </joint>

  <transmission name="wheel_tran11">
    <type>transmission_interface/SimpleTransmission</type>
    <actuator name="wheel_motor1">
      <hardwareInterface>hardware_interface/EffortJointInterface</hardwareInterface>
      <mechanicalReduction>1</mechanicalReduction>
    </actuator>
    <joint name="joint_left_forward">
      <hardwareInterface>hardware_interface/VelocityJointInterface</hardwareInterface>
    </joint>
  </transmission>


  <!-- Transmition -->
  <transmission name="wheel_tran22">
    <type>transmission_interface/SimpleTransmission</type>
    <actuator name="wheel_motor2">
      <hardwareInterface>hardware_interface/EffortJointInterface</hardwareInterface>
      <mechanicalReduction>1</mechanicalReduction>
    </actuator>
    <joint name="joint_right_forward">
      <hardwareInterface>hardware_interface/VelocityJointInterface</hardwareInterface>
    </joint>
  </transmission>


  <!-- Transmition -->
  <transmission name="wheel_tran33">
    <type>transmission_interface/SimpleTransmission</type>
    <actuator name="wheel_motor3">
      <hardwareInterface>hardware_interface/EffortJointInterface</hardwareInterface>
      <mechanicalReduction>1</mechanicalReduction>
    </actuator>
    <joint name="joint_left_back">
      <hardwareInterface>hardware_interface/VelocityJointInterface</hardwareInterface>
    </joint>
  </transmission>


  <!-- Transmition -->
  <transmission name="wheel_tran44">
    <type>transmission_interface/SimpleTransmission</type>
    <actuator name="wheel_motor4">
      <hardwareInterface>hardware_interface/EffortJointInterface</hardwareInterface>
      <mechanicalReduction>1</mechanicalReduction>
    </actuator>
    <joint name="joint_right_back">
      <hardwareInterface>hardware_interface/VelocityJointInterface</hardwareInterface>
    </joint>
  </transmission>


  <gazebo>
    <plugin name="gazebo_ros_control" filename="libgazebo_ros_control.so">
      <robotNamespace>/</robotNamespace>
      <robotSimType>gazebo_ros_control/DefaultRobotHWSim</robotSimType>
    </plugin>
  </gazebo>
  
</robot>
